Workbook

Sheet Vaciado
D1: 2024 | E1: 2025 | F1: 2026 | H1: 24/25 | I1: 25/26 | O1: MUS$
C2: Total de Clientes | D2: =Flujos!B8 -> 130 | E2: =Flujos!C8 -> 387.5 | F2: =Flujos!D8 -> 794.5 | H2: =(E2-D2)/D2 -> 1.9807692 | I2: =(F2-E2)/E2 -> 1.0503226 | L2: Valor Estocástico | O2: ='Para reporte'!G92 -> 716.63374 | P2: Corresponde al menor valor posible (MUS$)
C3: Ingresos (MUS$) | D3: =Flujos!B12 -> 1564.5643 | E3: =Flujos!C12 -> 3364.821 | F3: =Flujos!D12 -> 5160.3447 | H3: =(E3-D3)/D3 -> 1.1506441 | I3: =(F3-E3)/E3 -> 0.53361639
D5: VAN Chile (MUS$) | E5: ='MAP VALUE'!R29 -> 2183.3686 | G5: VAN (MUS$) Int. | H5: =NPV(D29,Flujos!B100:D100) -> 6982.4394 | J5: =E5+H5 -> 9165.8081
B7: Rango de usuarios (unidades de usuarios) | G7: Plan de ventas (unidades de clientes)
B8: ID | C8: Rango de usuarios | G8: Tipo de cliente | H8: 2024
H9: Enero | I9: Febrero | J9: Marzo | K9: Abril | L9: Mayo | M9: Junio | N9: Julio | O9: Agosto | P9: Septiembre | Q9: Octubre | R9: Noviembre | S9: Diciembre
B10: A | C10: 1 | D10: 25 | G10: =B10 -> A | H10: 1 | I10: 0 | J10: 1 | K10: 3 | L10: 8 | M10: 8 | N10: 12 | O10: 16 | P10: 16 | Q10: 20 | R10: 20 | S10: 20
B11: B | C11: 1 | D11: 500 | G11: =B11 -> B | H11: 0 | I11: 0 | J11: 1 | K11: 2 | L11: 8 | M11: 8 | N11: 12 | O11: 12 | P11: 12 | Q11: 12 | R11: 12 | S11: 12
B12: C | C12: =D11+1 -> 501 | D12: 1000 | G12: =B12 -> C | H12: 0 | I12: 0 | J12: 0 | K12: 1 | L12: 2 | M12: 2 | N12: 4 | O12: 4 | P12: 4 | Q12: 4 | R12: 4 | S12: 4
B13: D | C13: =D12+1 -> 1001 | D13: + | G13: =B13 -> D | H13: 0 | I13: 0 | J13: 0 | K13: 1 | L13: 1 | M13: 1 | N13: 2 | O13: 2 | P13: 2 | Q13: 2 | R13: 2 | S13: 2
B14: E | G14: =B14 -> E
C16: Valor UF | D16: 37000 | G16: Valor Paq. UF | H16: 2024 | T16: 2025 y 2026
C17: CLP/USD | D17: 900 | H17: Enero | I17: Febrero | J17: Marzo | K17: Abril | L17: Mayo | M17: Junio | N17: Julio | O17: Agosto | P17: Septiembre | Q17: Octubre | R17: Noviembre | S17: Diciembre
G18: =B10 -> A | H18: 30 | I18: 30 | J18: 30 | K18: 30 | L18: 30 | M18: 30 | N18: 30 | O18: 30 | P18: 30 | Q18: 30 | R18: 30 | S18: 30 | T18: 30
D19: MUS$ | G19: =B11 -> B | H19: 100 | I19: 100 | J19: 100 | K19: 100 | L19: 100 | M19: 100 | N19: 100 | O19: 100 | P19: 100 | Q19: 100 | R19: 100 | S19: 100 | T19: 100
C20: Inversión por recuperar | D20: 0 | G20: =B12 -> C | H20: 350 | I20: 350 | J20: 350 | K20: 350 | L20: 350 | M20: 350 | N20: 350 | O20: 350 | P20: 350 | Q20: 350 | R20: 350 | S20: 350 | T20: 350
C21: Cuentas Socios | D21: =63200/D17 -> 70.222222 | G21: =B13 -> D | H21: 1000 | I21: 1000 | J21: 1000 | K21: 1000 | L21: 1000 | M21: 1000 | N21: 1000 | O21: 1000 | P21: 1000 | Q21: 1000 | R21: 1000 | S21: 1000 | T21: 1000
C22: Pasivos de L. Plazo | D22: 0 | G22: =B14 -> E
B24: Beta | C24: 1.28 | D24: Information System | G24: Tipo de cliente | H24: MoM
B25: BCP | C25: 3 años | D25: 0.055 | H25: 2025 | I25: 2026
B26: US T. | C26: 3 años | D26: 0.0442 | G26: =B10 -> A | H26: 0.01 | I26: 0.01
B27: IPSA | C27: 3 años | D27: 0.2 | G27: =B11 -> B | H27: 0.01 | I27: 0.01
C28: Prima por riesgo | D28: 0.1 | G28: =B12 -> C | H28: 0.01 | I28: 0.01
C29: Tasa de descuento: | D29: =((D26+(C24*(D27-D26)))+(D25-D26))+D28 -> 0.354424 | G29: =B13 -> D | H29: 0.01 | I29: 0.01
G30: =B14 -> E | H30: 0.01 | I30: 0.01
C32: Recurrencia | D32: 12 | E32: meses | G32: Piloto | H32: 2024
C33: CHURN | D33: 0.5 | E33: mensual | H33: Enero | I33: Febrero | J33: Marzo | K33: Abril | L33: Mayo | M33: Junio | N33: Julio | O33: Agosto | P33: Septiembre | Q33: Octubre | R33: Noviembre | S33: Diciembre
G34: Piloto | H34: 0 | I34: 0 | J34: 0 | K34: 0 | L34: 0 | M34: 0 | N34: 0 | O34: 0 | P34: 0 | Q34: 0 | R34: 0 | S34: 0
C35: Costos por cliente | D35: US$
C36: Servidor por cliente: | D36: 125 | G36: Ciclo de conversión en meses | K36: % de conversión a clientes del Piloto
G37: 3 | K37: 0.5
C38: Costos mensuales | D38: US$ | E38: MUS$ | G38: MoM de la experiencia piloto
C39: Costos de Cloud mensual: | D39: 125 | E39: =D39/1000 -> 0.125 | G39: 2025 | H39: 0
C40: Costos de Hosting mensual: | D40: 63 | E40: =D40/1000 -> 0.063 | G40: 2026 | H40: 0
C41: Costos de correos mensual: | D41: 125 | E41: =D41/1000 -> 0.125
C42: Costos de Herramientas mensual: | D42: 125 | E42: =D42/1000 -> 0.125
C43: Costos de Licencias mensual: | D43: 125 | E43: =D43/1000 -> 0.125 | I43: 2024 | J43: 2025 | K43: 2026
C44: Otros gastos I+D: | D44: 1000 | E44: =D44/1000 -> 1 | H44: Impuesto a la renta | I44: 0.125 | J44: 0.15 | K44: 0.15
C45: Compra de equipos | D45: 1000 | E45: =D45/1000 -> 1
...

Sheet Indicadores
A1: Variables | C1: Unidad. | D1: Enero | E1: Febrero | F1: Marzo | G1: Abril | H1: Mayo | I1: Junio | J1: Julio | K1: Agosto | L1: Septiembre | M1: Octubre | N1: Noviembre | O1: Diciembre
A2: Total de clientes | B2: =Vaciado!B10 -> A | C2: #
B3: =Vaciado!B11 -> B | C3: #
B4: =Vaciado!B12 -> C | C4: #
B5: =Vaciado!B13 -> D | C5: #
B6: =Vaciado!B14 -> E | C6: #
A7: Precio Promedio Chile | B7: =Vaciado!B10 -> A | C7: UF
B8: =Vaciado!B11 -> B | C8: UF
B9: =Vaciado!B12 -> C | C9: UF
B10: =Vaciado!B13 -> D | C10: UF
B11: =Vaciado!B14 -> E | C11: UF
A12: Variable | B12: Servidor por cliente | C12: US$
B13: Costos de Cloud mensual | C13: US$
B14: Costos de Hosting mensual | C14: US$
B15: Costos de correos mensual | C15: US$
B16: Costos de Herramientas mensual | C16: US$
B17: Costos de Licencias mensual | C17: US$
B18: Otros gastos I+D | C18: US$
B19: Compra de equipos | C19: US$
A20: MKT | B20: Gasto de Marketing y Difusión | C20: CLP$
B21: Viaticos y viajes | C21: CLP$
B22: Comisión Partner | C22: %
A23: RRHH | B23: CCO | C23: MCLP$
B24: KAM | C24: MCLP$
B25: CTO | C25: MCLP$
B26: Desarrollador | C26: MCLP$
B27: Soporte | C27: MCLP$
B28: Operador | C28: MCLP$
B29: Expertos Revisión | C29: MCLP$
B30: CEO | C30: MCLP$
B31: CFO | C31: MCLP$
B32: Contadora | C32: MCLP$
A33: Comisiones | B33: Comisión del CEO | C33: %
B34: Comisión Operador | C34: %
B35: Comisión CTO | C35: %
B36: Comisión KAM | C36: %
B37: Comisión CCO | C37: %
A38: Brasil | B38: Ingresos reales acumulados | C38: MUS$
B39: Pagos directos acumulados | C39: MUS$
A40: Colombia | B40: Ingresos reales acumulados | C40: MUS$
...

Sheet Dashboard
B2: MUS$ | C2: 2024 | D2: 2025 | E2: 2026 | I2: MUS$ | J2: Ene | K2: Feb | L2: Mar | M2: Abr | N2: May | O2: Jun | P2: Jul | Q2: Ago | R2: Sept | S2: Oct | T2: Nov | U2: Dic | V2: 2024 | W2: 2025 | X2: 2026
B3: Ventas Chile | C3: ='Para reporte'!J28 -> 1564.5643 | D3: ='Para reporte'!K28 -> 3364.821 | E3: ='Para reporte'!L28 -> 5160.3447 | I3: Ventas Chile 2024 | J3: =Flujos!E12 -> 1.2333333 | K3: =Flujos!F12 -> 0 | L3: =Flujos!G12 -> 5.3444444 | M3: =Flujos!H12 -> 67.422222 | N3: =Flujos!I12 -> 112.64444 | O3: =Flujos!J12 -> 112.64444 | P3: =Flujos!K12 -> 203.91111 | Q3: =Flujos!L12 -> 208.84444 | ... U3: =Flujos!P12 -> 216.11987 | V3: =SUM(J3:U3) -> 1564.5643 | W3: ='Para reporte'!K13 -> 3364.821 | X3: ='Para reporte'!L13 -> 5160.3447
B4: Ventas Internacionales | C4: =Flujos!B95 -> 1760.1349 | D4: =Flujos!C85 -> 6412.4651 | E4: =Flujos!D85 -> 10365.22 | I4: Vtas Acum. Chile | J4: =J3 -> 1.2333333 | K4: =J4+K3 -> 1.2333333 | L4: =K4+L3 -> 6.5777778 | M4: =L4+M3 -> 74 | N4: =M4+N3 -> 186.64444 | O4: =N4+O3 -> 299.28889 | P4: =O4+P3 -> 503.2 | Q4: =P4+Q3 -> 712.04444 | R4: =Q4+R3 -> 920.88889 | ... U4: =T4+U3 -> 1564.5643 | V4: =U4 -> 1564.5643 | W4: =W3 -> 3364.821 | X4: =X3 -> 5160.3447
B5: Total de Ventas | C5: =C3+C4 -> 3324.6992 | D5: =D3+D4 -> 9777.2861 | E5: =E3+E4 -> 15525.565 | I5: YTD /Target ScaleX | J5: =($C$10/12) -> 355.10974 | K5: =($C$10/12)+J5 -> 710.21948 | L5: =($C$10/12)+K5 -> 1065.3292 | M5: =($C$10/12)+L5 -> 1420.439 | N5: =($C$10/12)+M5 -> 1775.5487 | O5: =($C$10/12)+N5 -> 2130.6584 | P5: =($C$10/12)+O5 -> 2485.7682 | Q5: =($C$10/12)+P5 -> 2840.8779 | R5: =($C$10/12)+Q5 -> 3195.9877 | ... U5: =($C$10/12)+T5 -> 4261.3169 | V5: =U5 -> 4261.3169 | W5: =D10 -> 4389.1564 | X5: =E10 -> 4520.8311
I6: Clientes nuevos acum. Chile | J6: =P.Comercial!H10 -> 1 | K6: =P.Comercial!I10+J6 -> 1 | L6: =P.Comercial!J10+K6 -> 3 | M6: =P.Comercial!K10+L6 -> 10 | N6: =P.Comercial!L10+M6 -> 29 | O6: =P.Comercial!M10+N6 -> 48 | P6: =P.Comercial!N10+O6 -> 78 | Q6: =P.Comercial!O10+P6 -> 112 | R6: =P.Comercial!P10+Q6 -> 146 | ... U6: =P.Comercial!S10+T6 -> 260 | V6: ='Para reporte'!J3 -> 260 | W6: ='Para reporte'!K3 -> 515 | X6: ='Para reporte'!L3 -> 814
B7: MUS$ sobre o bajo el eq. s/Chile | C7: =Metas!C15 -> 157.6428 | D7: =Metas!D15 -> 655.71173 | E7: =Metas!E15 -> 1177.6093 | I7: Clientes para target ScaleX | J7: =J5/'Unit Economics'!$C$3 -> 59.125781 | K7: =K5/'Unit Economics'!$C$3 -> 118.25156 | L7: =L5/'Unit Economics'!$C$3 -> 177.37734 | M7: =M5/'Unit Economics'!$C$3 -> 236.50313 | N7: =N5/'Unit Economics'!$C$3 -> 295.62891 | O7: =O5/'Unit Economics'!$C$3 -> 354.75469 | P7: =P5/'Unit Economics'!$C$3 -> 413.88047 | Q7: =Q5/'Unit Economics'!$C$3 -> 473.00625 | ... U7: =U5/'Unit Economics'!$C$3 -> 709.50938 | V7: =V5/'Unit Economics'!C3 -> 709.50938 | W7: =W5/'Unit Economics'!D3 -> 866.13814 | X7: =X5/'Unit Economics'!E3 -> 1077.13
B8: Down/Upside | C8: =Metas!C16 -> 1.112048 | D8: =Metas!D16 -> 1.2420396 | E8: =Metas!E16 -> 1.2956785
B10: ScaleX target | C10: =Metas!E7 -> 4261.3169 | D10: =Metas!E8 -> 4389.1564 | E10: =Metas!E9 -> 4520.8311
B11: Down/Upside ventas s/Chile | C11: =(C3-C10)/C3 -> -1.7236444 | D11: =(D3-D10)/D3 -> -0.30442492 | E11: =(E3-E10)/E3 -> 0.12392846
B12: Down/Upside ventas total | C12: =(C5-C10)/C5 -> -0.28171503 | D12: =(D5-D10)/D5 -> 0.55108643 | E12: =(E5-E10)/E5 -> 0.70881375
B15: MUS$ | C15: 2024 | D15: 2025 | E15: 2026
B16: Max Capital de Trabajo | C16: ='Unit Economics'!C22 -> 208.96388 | D16: ='Unit Economics'!D22 -> 161.27352 | E16: ='Unit Economics'!E22 -> 154.56499
B17: Var % anual | D17: =(D16-C16)/C16 -> -0.22822299 | E17: =(E16-D16)/D16 -> -0.041597254
B18: Bootstraping | C18: =IF(C16>'Unit Economics'!C21,'Unit Economics'!C20,'Unit Economics'!C21) -> 208.96388 | D18: =D16 -> 161.27352 | E18: =E16 -> 154.56499
B19: Bootstraping menos remanente d/equilibrio | C19: =C7-C18 -> -51.321082 | D19: =D7-D18 -> 494.43821 | E19: =E7-E18 -> 1023.0443
B21: Cifras en MUS$ | C21: 2024 | D21: 2025 | E21: 2026 | F21: Target
B22: Total de Ingresos | C22: ='Para reporte'!J47 -> 1564.5643 | D22: ='Para reporte'!K47 -> 3364.821 | E22: ='Para reporte'!L47 -> 5160.3447 | F22: > MUS$1.000 (3 año)
B23: Costos Operacionales | C23: ='Para reporte'!J48 -> 121.79428 | D23: ='Para reporte'!K48 -> 268.29195 | E23: ='Para reporte'!L48 -> 389.09051
B24: Gross Profit (%) | C24: =(C22-C23)/C22 -> 0.92215451 | D24: =(D22-D23)/D22 -> 0.92026561 | E24: =(E22-E23)/E22 -> 0.9245999 | F24: > 90%
B25: Gastos del CAC | C25: ='Para reporte'!J49 -> 385.07704 | D25: ='Para reporte'!K49 -> 783.32729 | E25: ='Para reporte'!L49 -> 1180.1625
B26: CAC por c/ cliente nuevo (MUS$) | C26: =Metas!C22 -> 1.4810655 | D26: =Metas!D22 -> 1.5210239 | E26: =Metas!E22 -> 1.4498311 | F26: < CAC MUS$ | G26: 10
B27: Gastos de Adm. y ventas | C27: ='Para reporte'!J50 -> 328.98422 | D27: ='Para reporte'!K50 -> 429.33039 | E27: ='Para reporte'!L50 -> 529.95657
B28: EBITDA | C28: ='Para reporte'!J51 -> 728.70878 | D28: ='Para reporte'!K51 -> 1883.8714 | E28: ='Para reporte'!L51 -> 3061.1351 | F28: > MUS$0
B29: EBITDA en % de los ingresos | C29: ='Para reporte'!J52 -> 0.46575828 | D29: ='Para reporte'!K52 -> 0.55987269 | E29: ='Para reporte'!L52 -> 0.59320361 | F29: > | G29: 0
C31: Proyectado | D31: Target
B32: Bootstraping 3y (MUS$) | C32: =C18+D18+E18 -> 524.80239 | D32: < MUS$ | E32: 350
B33: Breakeven (meses) | C33: =SUM(Flujos!E56:AN56) -> 3 | D33: < x meses | E33: 4
B34: Payback (meses) | C34: =SUM(Flujos!E58:AN58) -> 10 | D34: < x meses | E34: 12

Sheet Unit Economics
C2: 2024 | D2: 2025 | E2: 2026 | F2: Proyecto
B3: Ticket promedio (MUS$) | C3: ='Para reporte'!J23 -> 6.006005 | D3: ='Para reporte'!K23 -> 5.0675016 | E3: ='Para reporte'!L23 -> 4.1971083 | F3: ='Para reporte'!M16 -> 4.6841829 | G3: Ingresos / Cliente nuevos | L3: =C15 -> 1564.5643 | M3: =D15 -> 3364.821 | N3: =E15 -> 5160.3447 | O3: =L3+M3+N3 -> 10089.73
B4: Recurrencia (veces) | C4: =Flujos!B10/Flujos!B4 -> 1.0019231 | D4: =Flujos!C10/Flujos!C4 -> 1.2893204 | E4: =Flujos!D10/Flujos!D4 -> 1.5104423 | F4: =((Flujos!B10+Flujos!C10+Flujos!D10)/(Flujos!B4+Flujos!C4+Flujos!D4)) -> 1.3555695 | G4: veces / cliente | L4: =C16 -> 0.0014969608 | M4: =D16 -> 0.20742359 | N4: =E16 -> 0.37716047 | O4: =O5/O3 -> 0.26230269
B5: CAC (MUS$) | C5: ='Para reporte'!J42/'Para reporte'!J3 -> 1.4810655 | D5: ='Para reporte'!K42/'Para reporte'!K3 -> 1.5210239 | E5: ='Para reporte'!L42/'Para reporte'!L3 -> 1.4498311 | F5: ='Para reporte'!M42/'Para reporte'!M3 -> 1.4780156 | G5: Costo de adqusición por cada cliente nuevo | L5: =L3*L4 -> 2.3420915 | M5: =M3*M4 -> 697.94326 | N5: =N3*N4 -> 1946.278 | O5: =SUM(L5:N5) -> 2646.5634
B6: ARPU (%) | C6: ='Para reporte'!J52 -> 0.46575828 | D6: ='Para reporte'!K52 -> 0.55987269 | E6: ='Para reporte'!L52 -> 0.59320361 | F6: ='Unit Economics'!C24 -> 0.46575828 | G6: % de los ingresos que deja cada cliente | L6: =(C10*12) -> 260 | M6: =(D10*12) -> 515 | N6: =(E10*12) -> 814
C9: 2024 | D9: 2025 | E9: 2026 | F9: Proyecto
B10: Adqusición de clientes | C10: =(Flujos!B4+Flujos!B5)/12 -> 21.666667 | D10: =(Flujos!C4+Flujos!C5)/12 -> 42.916667 | E10: =(Flujos!D4+Flujos!D5)/12 -> 67.833333 | F10: ='MAP VALUE'!C7 -> 44.138889 | G10: Clientes nuevos por mes
B11: MoM | C11: =(POWER(('Para reporte'!J3/1),(1/11)))-1 -> 0.65784159 | D11: =(POWER(('Para reporte'!K3/'Para reporte'!J3),(1/11)))-1 -> 0.064106015 | E11: =(POWER(('Para reporte'!L3/'Para reporte'!K3),(1/11)))-1 -> 0.042495739 | F11: ='MAP VALUE'!D4 -> 0.18523831 | G11: tasa de crecimiento mensual de clientes
B12: CHURN | C12: =(POWER((-'Para reporte'!J6/1),(1/11)))-1 -> 0.55659872 | D12: =(POWER((-'Para reporte'!K6/1),(1/11)))-1 -> 0.65638606 | E12: =(POWER((-'Para reporte'!L6/1),(1/11)))-1 -> 0.72677541 | F12: ='MAP VALUE'!G7 -> 0.64658673 | G12: tasa mensual de pérdida de clientes
C14: 2024 | D14: 2025 | E14: 2026 | F14: Proyecto | L14: =C15+D15+E15 -> 10089.73 | M14: Total | N14: =L14/$L$14 -> 1 | P14: 0.47147173
B15: Ingresos totales Chile (MUS$) | C15: =Flujos!B12 -> 1564.5643 | D15: =Flujos!C12 -> 3364.821 | E15: =Flujos!D12 -> 5160.3447 | F15: =C15+D15+E15 -> 10089.73 | L15: =(C15*C16)+(D15*D16)+(E15*E16) -> 2646.5634 | M15: Recurrentes | N15: =L15/$L$14 -> 0.26230269 | O15: =O16 -> 1589 | P15: =P16 -> 4.6841829 | Q15: =O15*P15*P14 -> 3509.2427
B16: MRR | C16: =P.Comercial!C73/P.Comercial!C48 -> 0.0014969608 | D16: =P.Comercial!D73/P.Comercial!D48 -> 0.20742359 | E16: =P.Comercial!E73/P.Comercial!E48 -> 0.37716047 | G16: Ingresos recurrentes mensuales como % de los ingresos totales | L16: =L14-L15 -> 7443.1667 | M16: Nuevos | N16: =L16/$L$14 -> 0.73769731 | O16: ='MAP VALUE'!D11 -> 1589 | P16: ='MAP VALUE'!B11 -> 4.6841829 | Q16: =O16*P16 -> 7443.1667
B17: Gross Profitt | C17: ='Para reporte'!J38 -> 0.92215451 | D17: ='Para reporte'!K38 -> 0.92026561 | E17: ='Para reporte'!L38 -> 0.9245999 | F17: ='MAP VALUE'!J11 -> 0.92234001 | G17: % de los ingresos que son los costos operacionales
B18: CASH BURN RATE | C18: =('Para reporte'!J36+'Para reporte'!J42+'Para reporte'!J50)/360 -> 2.3218209 | D18: =('Para reporte'!K36+'Para reporte'!K42+'Para reporte'!K50)/360 -> 4.113749 | E18: =('Para reporte'!L36+'Para reporte'!L42+'Para reporte'!L50)/360 -> 5.8311377 | F18: ='MAP VALUE'!F26 -> 2.3218209 | G18: MUS$ gastos por día
B19: Ciclo Productivo (días) | C19: =Vaciado!$C$80 -> 90 | D19: =Vaciado!$C$80 -> 90 | E19: =Vaciado!$C$80 -> 90 | F19: ='MAP VALUE'!H26 -> 90 | G19: Tiempo entre la adqusición y monetización de un cliente
B20: Capital de trabajo A | C20: =C18*C19 -> 208.96388 | D20: =D18*D19 -> 370.23741 | E20: =E18*E19 -> 524.80239 | F20: =C20 -> 208.96388 | G20: Monto para cubrir un ciclo productivo
B21: Capital de trabajo B | C21: =Flujos!E72 -> -182.63922 | F21: =C21 -> -182.63922 | G21: Flujos negativos del período
B22: Max Capital de Trabajo | C22: =MAX(C21,C20) -> 208.96388 | D22: =MAX(D21,D20)-C22 -> 161.27352 | E22: =MAX(E21,E20)-D22-C22 -> 154.56499 | F22: =MAX(F20,F21) -> 208.96388 | G22: Max. Capital de trabajo encontrado aplicando dos metodologías
B23: Gross Profit | C23: ='Para reporte'!J38 -> 0.92215451 | D23: ='Para reporte'!K38 -> 0.92026561 | E23: ='Para reporte'!L38 -> 0.9245999 | F23: =F17 -> 0.92234001 | G23: Resultado operacional / ingresos (Chile)
B24: Margen de EBITDA | C24: ='Para reporte'!J52 -> 0.46575828 | D24: ='Para reporte'!K52 -> 0.55987269 | E24: ='Para reporte'!L52 -> 0.59320361 | F24: ='MAP VALUE'!G17 -> 0.46575828 | G24: EBITDA / ingresos (Chile)
B26: MUS$ | C26: 2024 | D26: 2025 | E26: 2026
B27: Ingresos Chile | C27: =C15 -> 1564.5643 | D27: =D15 -> 3364.821 | E27: =E15 -> 5160.3447
B28: Ingresos Brasil | C28: =Flujos!B95 -> 1760.1349 | D28: =Flujos!C95 -> 4372.1353 | E28: =Flujos!D95 -> 7067.1956
B29: Ingresos Colombia | C29: =Flujos!B96 -> 821.39626 | D29: =Flujos!C96 -> 2040.3298 | E29: =Flujos!D96 -> 3298.0246
B30: Ingresos Totales | C30: =C27+C28+C29 -> 4146.0954 | D30: =D27+D28+D29 -> 9777.2861 | E30: =E27+E28+E29 -> 15525.565
B32: % de Ingresos Chile | C32: =C27/$C$30 -> 0.37735849 | D32: =D27/$D$30 -> 0.34414673 | E32: =E27/$E$30 -> 0.33237726
B33: % de Ingresos Brasil | C33: =C28/$C$30 -> 0.4245283 | D33: =D28/$D$30 -> 0.44717268 | E33: =E28/$E$30 -> 0.45519733
B34: % de Ingresos Colombia | C34: =C29/$C$30 -> 0.19811321 | D34: =D29/$D$30 -> 0.20868059 | E34: =E29/$E$30 -> 0.21242542
B36: % Ingreso nacional | C36: =C32 -> 0.37735849 | D36: =D32 -> 0.34414673 | E36: =E32 -> 0.33237726
B37: % Ingreso Internacional | C37: =C33+C34 -> 0.62264151 | D37: =D33+D34 -> 0.65585327 | E37: =E33+E34 -> 0.66762274

Sheet MAP VALUE
A1: Cifras en MUS$ (miles de dólares de Estados Unidos)
D3: MoM | R3: BREAKEVEN: | S3: =Dashboard!C33 -> 3 | T3: Meses
D4: 0.18523831 | R4: PAYBACK: | S4: =Dashboard!C34 -> 10 | T4: Meses
C6: Adquisición Mensual | D6: X | E6: Horizonte de eval. (años) | F6: X | G6: CHURN (mensual real) | H6: X | I6: Frecuencia de compra (meses) | N6: US.T | P6: BCP 3 años | R6: IPSA Anual
C7: =AVERAGE('Unit Economics'!C10:E10) -> 44.138889 | E7: 3 | G7: =AVERAGE('Unit Economics'!C12:E12) -> 0.64658673 | I7: 12 | N7: =Vaciado!D26 -> 0.0442 | P7: =Vaciado!D25 -> 0.055 | R7: =Vaciado!D27 -> 0.2
P9: Beta
B10: Ticket Promedio | C10: X | D10: Clientes Monetizados | E10: X | F10: Recurrencia | G10: = | H10: Ingresos | I10: X | J10: G.P. | K10: = | L10: Resultado Op. | P10: =Vaciado!D24 -> Information System
B11: ='Para reporte'!M16 -> 4.6841829 | D11: =(C7*(12*E7)) -> 1589 | F11: =((Flujos!B10+Flujos!C10+Flujos!D10)/(Flujos!B4+Flujos!C4+Flujos!D4)) -> 1.3555695 | H11: =B11*D11*F11 -> 10089.73 | J11: =AVERAGE('Unit Economics'!C17:E17) -> 0.92234001 | L11: =(H11*J11) -> 9306.1616 | P11: =Vaciado!C24 -> 1.28
D12: x
D13: CAC | I13: (-) | J13: Gastos del CAC | K13: = | L13: Resultado d/CAC | P13: Tasa de descuento
D14: ='Unit Economics'!F5 -> 1.4780156 | J14: =D14*D11 -> 2348.5668 | L14: =L11-J14 -> 6957.5948 | P14: =(N7+(P11*(R7-N7)))+(P7-N7) -> 0.254424
C16: Ingresos - CAC | E16: LTV | G16: ARPU | I16: (-) | J16: Gastos de Administración | K16: = | L16: EBITDA | P16: CASTIGO x RIESGO
C17: =B11-D14 -> 3.2061673 | E17: =C17*F11 -> 4.3461827 | G17: ='Unit Economics'!C24 -> 0.46575828 | J17: =SUM(Dashboard!C27:E27) -> 1288.2712 | L17: =L14-J17 -> 5669.3236 | P17: =Vaciado!D28 -> 0.1
I19: / (1- … ) | J19: Impuestos efectivos | K19: x | L19: Flujos d/Impuestos | N19: Tasa de descuento nominal
J20: ='Para reporte'!O65 -> 0.11459869 | L20: =L17*(1-J20) -> 5019.6266 | N20: =P14+P17 -> 0.354424
I22: (-) | J22: Capital de Trabajo x Flujos | K22: - | L22: Flujos s/ Inv. Inicial | M22: X | N22: Tasa de descuento real | O22: = | P22: VAN de los flujos | Q22: - | R22: Pasivos & Obligaciones
J23: =-'Para reporte'!J63 -> 182.63922 | L23: =L20-J23 -> 4836.9873 | N23: ='Para reporte'!Q66 -> 0.47135031 | P23: =L23*N23 -> 2279.9155 | R23: =(Vaciado!D21+Vaciado!D22) -> 70.222222
F25: Cash Burn Rate | G25: X | H25: Ciclo Productivo | I25: = | J25: Capital de Trabajo x Ciclo Op. | Q25: - | R25: Bootstraping | T25: Inversión Total (MUS$) | W25: =T26/R29 -> 0.12786943
F26: ='Unit Economics'!C18 -> 2.3218209 | H26: ='Unit Economics'!C19 -> 90 | J26: =F26*H26 -> 208.96388 | R26: =J26-J23 -> 26.324662 | T26: =J26+R23 -> 279.18611
Q28: = | R28: Valor | S28: =R29/'Unit Economics'!C15 -> 1.3955122 | T28: Ingresos primer año
R29: =P23-R23-R26 -> 2183.3686 | S29: =R29/'Para reporte'!J51 -> 2.9962156 | T29: EBITDA primer año
L32: País | M32: Comisión | N32: Veces Ingresos Chile | O32: días pago ingresos | P32: VALOR (VAN) adicional | R32: VAN Internacional | T32: Valor Total (MUS$) | W32: =T33/R29 -> 4.1980122
L33: Brasil | M33: =Vaciado!D75 -> 0.15 | N33: =Vaciado!E75 -> 1.5 | O33: =Vaciado!F75 -> 90 | P33: =Flujos!E106 -> 4881.6539 | R33: =P33+P34 -> 6982.4394 | T33: =R29+P33+P34 -> 9165.8081
L34: Colombia | M34: =Vaciado!D76 -> 0.2 | N34: =Vaciado!E76 -> 0.7 | O34: =Vaciado!F76 -> 90 | P34: =Flujos!E112 -> 2100.7856
T36: Empresa valorizada por A.Maureira & Co.

Sheet Cap.Table
B3: (MUS$) | C3: Common | D3: Loan | E3: Seed 1 | F3: Seed 2 | G3: VC | H3: Options | I3: Total | J3: Fully Diluted
B4: Bárbara Pantoja P. | C4: =10000/Vaciado!D17 -> 11.111111 | I4: =SUM(C4:H4) -> 11.111111 | J4: =I4/$I$7 -> 0.33333333
B5: Rodrigo Hermosilla P. | C5: =C4 -> 11.111111 | I5: =SUM(C5:H5) -> 11.111111 | J5: =I5/$I$7 -> 0.33333333
B6: Lionel Valenzuela O. | C6: =C4 -> 11.111111 | I6: =SUM(C6:H6) -> 11.111111 | J6: =I6/$I$7 -> 0.33333333
B7: Total | C7: =SUM(C4:C6) -> 33.333333 | D7: =SUM(D4:D6) -> 0 | E7: =SUM(E4:E6) -> 0 | F7: =SUM(F4:F6) -> 0 | G7: =SUM(G4:G6) -> 0 | H7: =SUM(H4:H6) -> 0 | I7: =SUM(I4:I6) -> 33.333333 | J7: =SUM(J4:J6) -> 1
B10: (MUS$) | C10: Common | D10: Loan | E10: Seed 1 | F10: Seed 2 | G10: VC | H10: Options | I10: Total | J10: Fully Diluted
B11: =B4 -> Bárbara Pantoja P. | C11: =C4 -> 11.111111 | I11: =SUM(C11:H11) -> 11.111111 | J11: =L11 -> 0.29071019 | L11: =(1/3)-(J16/3) -> 0.29071019
B12: =B5 -> Rodrigo Hermosilla P. | C12: =C5 -> 11.111111 | I12: =SUM(C12:H12) -> 11.111111 | J12: =L11 -> 0.29071019
B13: =B6 -> Lionel Valenzuela O. | C13: =C6 -> 11.111111 | I13: =SUM(C13:H13) -> 11.111111 | J13: =L11 -> 0.29071019
B14: FONDO 1 | E14: 100 | I14: =SUM(C14:H14) -> 100 | J14: 0
B15: FONDO 2 | E15: 100 | I15: =SUM(C15:H15) -> 100 | J15: 0
B16: Venture Capital | G16: ='MAP VALUE'!T26 -> 279.18611 | I16: =SUM(C16:H16) -> 279.18611 | J16: =I16/I19 -> 0.12786943
B17: Total | C17: =SUM(C11:C16) -> 33.333333 | D17: =SUM(D11:D16) -> 0 | E17: =SUM(E11:E16) -> 200 | F17: =SUM(F11:F16) -> 0 | G17: =SUM(G11:G16) -> 279.18611 | H17: =SUM(H11:H16) -> 0 | I17: =SUM(I11:I16) -> 512.51944 | J17: =SUM(J11:J16) -> 1
H19: Valor Postmoney | I19: =Vaciado!E5 -> 2183.3686

Sheet Para reporte
B2: ID | C2: Rango de usuarios | E2: Valor Paquete | J2: 2024 | K2: 2025 | L2: 2026 | P2: 2024 | Q2: 2025 | R2: 2026
E3: UF | F3: MUS$ | I3: Clientes nuevos | J3: =SUM(P.Comercial!H10:S10) -> 260 | K3: =SUM(P.Comercial!T10:AE10) -> 515 | L3: =SUM(P.Comercial!AF10:AQ10) -> 814 | M3: =SUM(J3:L3) -> 1589 | O3: Ingresos por clientes nuevos | P3: =J26 -> 1562.2222 | Q3: =K26 -> 2666.8778 | R3: =L26 -> 3214.0667
B4: =Vaciado!B10 -> A | C4: =Vaciado!C10 -> 1 | D4: =Vaciado!D10 -> 25 | E4: =Vaciado!T18 -> 30 | F4: =((E4*Vaciado!$D$16)/Vaciado!$D$17)/1000 -> 1.2333333 | I4: Clientes x Exp. Piloto | J4: =SUM(P.Comercial!H14:S14) -> 0 | K4: =SUM(P.Comercial!T14:AE14) -> 0 | L4: =SUM(P.Comercial!AF14:AQ14) -> 0 | O4: Ingresos recurrentes | P4: =J27 -> 2.3420915 | Q4: =K27 -> 697.94326 | R4: =L27 -> 1946.278
B5: =Vaciado!B11 -> B | C5: =Vaciado!C11 -> 1 | D5: =Vaciado!D11 -> 500 | E5: =Vaciado!T19 -> 100 | F5: =((E5*Vaciado!$D$16)/Vaciado!$D$17)/1000 -> 4.1111111 | I5: Total de Clientes Adquiridos | J5: =J3+J4 -> 260 | K5: =K3+K4 -> 515 | L5: =L3+L4 -> 814 | O5: CAC total | P5: =-J42 -> -385.07704 | Q5: =-K42 -> -783.32729 | R5: =-L42 -> -1180.1625
B6: =Vaciado!B12 -> C | C6: =Vaciado!C12 -> 501 | D6: =Vaciado!D12 -> 1000 | E6: =Vaciado!T20 -> 350 | F6: =((E6*Vaciado!$D$16)/Vaciado!$D$17)/1000 -> 14.388889 | I6: CHURN de Clientes | J6: =SUM(P.Comercial!H26:S26) -> -130 | K6: =SUM(P.Comercial!T26:AE26) -> -257.5 | L6: =SUM(P.Comercial!AF26:AQ26) -> -407
B7: =Vaciado!B13 -> D | C7: =Vaciado!C13 -> 1001 | D7: =Vaciado!D13 -> + | E7: =Vaciado!T21 -> 1000 | F7: =((E7*Vaciado!$D$16)/Vaciado!$D$17)/1000 -> 41.111111 | I7: Clientes acumulados | J7: =J5+J6 -> 130 | K7: =K5+K6+J7 -> 387.5 | L7: =L5+L6+K7 -> 794.5
B8: =Vaciado!B14 -> E | C8: =Vaciado!C14 -> 0 | D8: =Vaciado!D14 -> 0 | E8: =Vaciado!T22 -> 0 | F8: =((E8*Vaciado!$D$16)/Vaciado!$D$17)/1000 -> 0
J9: 2024 | K9: 2025 | L9: 2026
I10: Total de servicios | J10: =SUM(P.Comercial!H44:S44) -> 260.5 | K10: =SUM(P.Comercial!T44:AE44) -> 664 | L10: =SUM(P.Comercial!AF44:AQ44) -> 1229.5 | M10: =SUM(J10:L10) -> 2154
B11: Tipo de cliente | C11: Total de Clientes | F11: Total Adquiridos | G11: % de la Cartera
C12: 2024 | D12: 2025 | E12: 2026 | I12: Cifras en MUS$ | J12: 2024 | K12: 2025 | L12: 2026
B13: =Vaciado!B10 -> A | C13: =SUM(P.Comercial!H5:S5) -> 125 | D13: =SUM(P.Comercial!T5:AE5) -> 289 | E13: =SUM(P.Comercial!AF5:AQ5) -> 526 | F13: =SUM(C13:E13) -> 940 | G13: =IF(F13=0,0,F13/$F$18) -> 0.59156702 | I13: Ingresos totales | J13: =SUM(P.Comercial!H52:S52) -> 1564.5643 | K13: =SUM(P.Comercial!T52:AE52) -> 3364.821 | L13: =SUM(P.Comercial!AF52:AQ52) -> 5160.3447 | M13: =SUM(J13:L13) -> 10089.73
B14: =Vaciado!B11 -> B | C14: =SUM(P.Comercial!H6:S6) -> 91 | D14: =SUM(P.Comercial!T6:AE6) -> 154 | E14: =SUM(P.Comercial!AF6:AQ6) -> 216 | F14: =SUM(C14:E14) -> 461 | G14: =IF(F14=0,0,F14/$F$18) -> 0.29011957
B15: =Vaciado!B12 -> C | C15: =SUM(P.Comercial!H7:S7) -> 29 | D15: =SUM(P.Comercial!T7:AE7) -> 48 | E15: =SUM(P.Comercial!AF7:AQ7) -> 48 | F15: =SUM(C15:E15) -> 125 | G15: =IF(F15=0,0,F15/$F$18) -> 0.078665828 | I15: Cifras en MUS$ | J15: 2024 | K15: 2025 | L15: 2026 | M15: Proyecto
B16: =Vaciado!B13 -> D | C16: =SUM(P.Comercial!H8:S8) -> 15 | D16: =SUM(P.Comercial!T8:AE8) -> 24 | E16: =SUM(P.Comercial!AF8:AQ8) -> 24 | F16: =SUM(C16:E16) -> 63 | G16: =IF(F16=0,0,F16/$F$18) -> 0.039647577 | I16: Ticket promedio | J16: =IF(J10=0,0,J13/J10) -> 6.006005 | K16: =IF(K10=0,0,K13/K10) -> 5.0675016 | L16: =IF(L10=0,0,L13/L10) -> 4.1971083 | M16: =IF(M10=0,0,M13/M10) -> 4.6841829
B17: =Vaciado!B14 -> E | C17: =SUM(P.Comercial!H9:S9) -> 0 | D17: =SUM(P.Comercial!T9:AE9) -> 0 | E17: =SUM(P.Comercial!AF9:AQ9) -> 0 | F17: =SUM(C17:E17) -> 0 | G17: =IF(F17=0,0,F17/$F$18) -> 0 | J17: =J13/J3 -> 6.0175551 | K17: =K13/K3 -> 6.5336331 | L17: =L13/L3 -> 6.3394898 | M17: =M13/M3 -> 6.3497357
B18: Totales | C18: =SUM(C13:C17) -> 260 | D18: =SUM(D13:D17) -> 515 | E18: =SUM(E13:E17) -> 814 | F18: =SUM(F13:F17) -> 1589 | G18: =IF(F18=0,0,F18/$F$18) -> 1
I19: Cifras en MUS$ | J19: 2024 | K19: 2025 | L19: 2026 | M19: Proyecto
B20: Exp. Piloto | C20: Total de Clientes Adquiridos de Piloto | F20: Total Adquiridos | I20: Ticket promedio C. nuevos | J20: =IF(P.Comercial!C57=0,0,P.Comercial!C57/'Para reporte'!J3) -> 6.008547 | K20: =IF(P.Comercial!D57=0,0,P.Comercial!D57/'Para reporte'!K3) -> 5.1784035 | L20: =IF(P.Comercial!E57=0,0,P.Comercial!E57/'Para reporte'!L3) -> 3.9484848 | M20: =IF(P.Comercial!F57=0,0,P.Comercial!F57/'Para reporte'!M3) -> 0
C21: 2024 | D21: 2025 | E21: 2026 | I21: Ticket promedio C. Exp. P. | J21: =IF(J4=0,0,P.Comercial!C65/'Para reporte'!J4) -> 0 | K21: =IF(K4=0,0,P.Comercial!D65/'Para reporte'!K4) -> 0 | L21: =IF(L4=0,0,P.Comercial!E65/'Para reporte'!L4) -> 0 | M21: =IF(M4=0,0,P.Comercial!F65/'Para reporte'!M4) -> 0
B22: Piloto | C22: =SUM(P.Comercial!H14:S14) -> 0 | D22: =SUM(P.Comercial!T14:AE14) -> 0 | E22: =SUM(P.Comercial!AF14:AQ14) -> 0 | F22: =SUM(C22:E22) -> 0 | I22: Ticket promedio recurrentes | J22: =IF((J10-J5)=0,0,P.Comercial!C73/(J10-J5)) -> 4.6841829 | K22: =IF((K10-K5)=0,0,P.Comercial!D73/(K10-K5)) -> 4.6841829 | L22: =IF((L10-L5)=0,0,P.Comercial!E73/(L10-L5)) -> 4.6841829 | M22: =IF((M10-M5)=0,0,P.Comercial!F73/(M10-M5)) -> 0
I23: Ticket promedio ponderado | J23: =J16 -> 6.006005 | K23: =K16 -> 5.0675016 | L23: =L16 -> 4.1971083 | M23: =M16 -> 4.6841829
B25: Tipo de cliente | C25: Precio en MUS$ | D25: % de la Cartera | E25: Precio Prom MUS$ | I25: Cifras en MUS$ | J25: 2024 | K25: 2025 | L25: 2026
I26: Ingresos clientes nuevos | J26: =J20*J3 -> 1562.2222 | K26: =K20*K3 -> 2666.8778 | L26: =L20*L3 -> 3214.0667
B27: =Vaciado!B10 -> A | C27: =F4 -> 1.2333333 | D27: =G13 -> 0.59156702 | E27: =C27*D27 -> 0.72959933 | I27: Ingresos Recurrentes | J27: =(J10*J16)-J26 -> 2.3420915 | K27: =(K10*K16)-K26 -> 697.94326 | L27: =(L10*L16)-L26 -> 1946.278
B28: =Vaciado!B11 -> B | C28: =F5 -> 4.1111111 | D28: =G14 -> 0.29011957 | E28: =C28*D28 -> 1.1927138 | I28: Total de Ingresos | J28: =J26+J27 -> 1564.5643 | K28: =K26+K27 -> 3364.821 | L28: =L26+L27 -> 5160.3447
B29: =Vaciado!B12 -> C | C29: =F6 -> 14.388889 | D29: =G15 -> 0.078665828 | E29: =C29*D29 -> 1.1319139
B30: =Vaciado!B13 -> D | C30: =F7 -> 41.111111 | D30: =G16 -> 0.039647577 | E30: =C30*D30 -> 1.6299559
B31: =Vaciado!B14 -> E | C31: =F8 -> 0 | D31: =G17 -> 0 | E31: =C31*D31 -> 0 | I31: % del total de ingresos | J31: 2024 | K31: 2025 | L31: 2026
B32: Precio promedio ponderado | E32: =SUM(E27:E31) -> 4.6841829 | I32: Ingresos recurrentes | J32: =IF(J28=0,0,J27/J28) -> 0.0014969608 | K32: =IF(K28=0,0,K27/K28) -> 0.20742359 | L32: =IF(L28=0,0,L27/L28) -> 0.37716047
I34: Cifras en MUS$ | J34: 2024 | K34: 2025 | L34: 2026
D35: MUS$ | I35: Total de Ingresos | J35: =Flujos!B12 -> 1564.5643 | K35: =Flujos!C12 -> 3364.821 | L35: =Flujos!D12 -> 5160.3447
B36: Costos fijos mensuales | D36: =Vaciado!E39+Vaciado!E40+Vaciado!E41+Vaciado!E42+Vaciado!E43+Vaciado!E44+Vaciado!E45+Vaciado!E47+Vaciado!E50+Vaciado!E56+Vaciado!E57+Vaciado!E58+Vaciado!E59+Vaciado!E60+Vaciado!E61+Vaciado!E62+Vaciado!E63+Vaciado!E64+Vaciado!E65 -> 28.507444 | I36: Costos Operacionales | J36: =Flujos!B20 -> 121.79428 | K36: =Flujos!C20 -> 268.29195 | L36: =Flujos!D20 -> 389.09051 | N36: =J36/J35 -> 0.077845495
B37: Costos fijos anuales | D37: =D36*12 -> 342.08933 | I37: Resultado Operacional | J37: =J35-J36 -> 1442.77 | K37: =K35-K36 -> 3096.5291 | L37: =L35-L36 -> 4771.2542
I38: Gross Profit (%) | J38: =IF(J35=0,0,J37/J35) -> 0.92215451 | K38: =IF(K35=0,0,K37/K35) -> 0.92026561 | L38: =IF(L35=0,0,L37/L35) -> 0.9245999
C39: Ticket promedio: | D39: ='Unit Economics'!C3 -> 6.006005
C40: % Comprometido: | D40: =Vaciado!D68+Vaciado!D69+Vaciado!D70+Vaciado!D71+Vaciado!D72+Vaciado!D51 -> 0.315 | I40: Cifras en MUS$ | J40: 2024 | K40: 2025 | L40: 2026 | M40: Total
C41: Costos Unitarios: | D41: =Vaciado!D36/1000 -> 0.125 | I41: Total de Ingresos | J41: =Flujos!B12 -> 1564.5643 | K41: =Flujos!C12 -> 3364.821 | L41: =Flujos!D12 -> 5160.3447 | M41: =J41+K41+L41 -> 10089.73
C42: Costos variable por unidad: | D42: =D39*D40+D41 -> 2.0168916 | I42: Gastos del CAC | J42: =Flujos!B28 -> 385.07704 | K42: =Flujos!C28 -> 783.32729 | L42: =Flujos!D28 -> 1180.1625 | M42: =J42+K42+L42 -> 2348.5668
I43: Resultado d/ de CAC | J43: =J41-J42 -> 1179.4873 | K43: =K41-K42 -> 2581.4937 | L43: =L41-L42 -> 3980.1822 | M43: =M41-M42 -> 7741.1632
...

Sheet Flujos
E1: 1 | F1: 2 | G1: 3 | H1: 4 | I1: 5 | J1: 6 | K1: 7 | L1: 8 | M1: 9 | N1: 10 | O1: 11 | P1: 12 | Q1: 13 | R1: 14 | S1: 15 | T1: 16 | U1: 17 | V1: 18 | W1: 19 | X1: 20 | Y1: 21 | Z1: 22 | AA1: 23 | AB1: 24 | AC1: 25 | AD1: 26 | AE1: 27 | AF1: 28 | AG1: 29 | AH1: 30 | AI1: 31 | AJ1: 32 | AK1: 33 | AL1: 34 | AM1: 35 | AN1: 36
E2: 2024 | Q2: 2025 | AC2: 2026
B3: 2024 | C3: 2025 | D3: 2026 | E3: Enero | F3: Febrero | G3: Marzo | H3: Abril | I3: Mayo | J3: Junio | K3: Julio | L3: Agosto | M3: Septiembre | N3: Octubre | O3: Noviembre | P3: Diciembre | Q3: Enero | R3: Febrero | S3: Marzo | T3: Abril | U3: Mayo | V3: Junio | W3: Julio | X3: Agosto | Y3: Septiembre | Z3: Octubre | AA3: Noviembre | AB3: Diciembre | AC3: Enero | AD3: Febrero | AE3: Marzo | AF3: Abril | AG3: Mayo | AH3: Junio | AI3: Julio | AJ3: Agosto | AK3: Septiembre | AL3: Octubre | AM3: Noviembre | AN3: Diciembre
A4: Clientes nuevos | B4: =SUM(E4:P4) -> 260 | C4: =SUM(Q4:AB4) -> 515 | D4: =SUM(AC4:AN4) -> 814 | E4: =P.Comercial!H10 -> 1 | F4: =P.Comercial!I10 -> 0 | G4: =P.Comercial!J10 -> 2 | H4: =P.Comercial!K10 -> 7 | I4: =P.Comercial!L10 -> 19 | J4: =P.Comercial!M10 -> 19 | K4: =P.Comercial!N10 -> 30 | L4: =P.Comercial!O10 -> 34 | ... AN4: =P.Comercial!AQ10 -> 96
A5: Clientes Ex. Piloto | B5: =SUM(E5:P5) -> 0 | C5: =SUM(Q5:AB5) -> 0 | D5: =SUM(AC5:AN5) -> 0 | E5: =P.Comercial!H24 -> 0 | F5: =P.Comercial!I24 -> 0 | G5: =P.Comercial!J24 -> 0 | H5: =P.Comercial!K24 -> 0 | I5: =P.Comercial!L24 -> 0 | J5: =P.Comercial!M24 -> 0 | K5: =P.Comercial!N24 -> 0 | L5: =P.Comercial!O24 -> 0 | ... AN5: =P.Comercial!AQ24 -> 0
A6: Churn | B6: =SUM(E6:P6) -> -130 | C6: =SUM(Q6:AB6) -> -257.5 | D6: =SUM(AC6:AN6) -> -407 | E6: =P.Comercial!H26 -> -0.5 | F6: =P.Comercial!I26 -> 0 | G6: =P.Comercial!J26 -> -1 | H6: =P.Comercial!K26 -> -3.5 | I6: =P.Comercial!L26 -> -9.5 | J6: =P.Comercial!M26 -> -9.5 | K6: =P.Comercial!N26 -> -15 | L6: =P.Comercial!O26 -> -17 | ... AN6: =P.Comercial!AQ26 -> -48
A7: Base de clientes | B7: =SUM(E7:P7) -> 130 | C7: =SUM(Q7:AB7) -> 257.5 | D7: =SUM(AC7:AN7) -> 407 | E7: =E4+E5+E6 -> 0.5 | F7: =F4+F5+F6 -> 0 | G7: =G4+G5+G6 -> 1 | H7: =H4+H5+H6 -> 3.5 | I7: =I4+I5+I6 -> 9.5 | J7: =J4+J5+J6 -> 9.5 | K7: =K4+K5+K6 -> 15 | L7: =L4+L5+L6 -> 17 | ... AN7: =AN4+AN5+AN6 -> 48
A8: Clientes acumulados | B8: =P8 -> 130 | C8: =AB8 -> 387.5 | D8: =AN8 -> 794.5 | E8: =E7 -> 0.5 | F8: =E8+F7 -> 0.5 | G8: =F8+G7 -> 1.5 | H8: =G8+H7 -> 5 | I8: =H8+I7 -> 14.5 | J8: =I8+J7 -> 24 | K8: =J8+K7 -> 39 | L8: =K8+L7 -> 56 | M8: =L8+M7 -> 73 | ... AN8: =AM8+AN7 -> 794.5
A9: Servicios recurrentes | B9: =SUM(E9:P9) -> 0.5 | C9: =SUM(Q9:AB9) -> 149 | D9: =SUM(AC9:AN9) -> 415.5 | E9: =P.Comercial!H30 -> 0 | F9: =P.Comercial!I30 -> 0 | G9: =P.Comercial!J30 -> 0 | H9: =P.Comercial!K30 -> 0 | I9: =P.Comercial!L30 -> 0 | J9: =P.Comercial!M30 -> 0 | K9: =P.Comercial!N30 -> 0 | L9: =P.Comercial!O30 -> 0 | ... AN9: =P.Comercial!AQ30 -> 47.5
A10: Total de servicios | B10: =SUM(E10:P10) -> 260.5 | C10: =SUM(Q10:AB10) -> 664 | D10: =SUM(AC10:AN10) -> 1229.5 | E10: =E4+E5+E9 -> 1 | F10: =F4+F5+F9 -> 0 | G10: =G4+G5+G9 -> 2 | H10: =H4+H5+H9 -> 7 | I10: =I4+I5+I9 -> 19 | J10: =J4+J5+J9 -> 19 | K10: =K4+K5+K9 -> 30 | L10: =L4+L5+L9 -> 34 | ... AN10: =AN4+AN5+AN9 -> 143.5
A12: Total de Ingresos | B12: =SUM(E12:P12) -> 1564.5643 | C12: =SUM(Q12:AB12) -> 3364.821 | D12: =SUM(AC12:AN12) -> 5160.3447 | E12: =P.Comercial!H52 -> 1.2333333 | F12: =P.Comercial!I52 -> 0 | G12: =P.Comercial!J52 -> 5.3444444 | H12: =P.Comercial!K52 -> 67.422222 | I12: =P.Comercial!L52 -> 112.64444 | J12: =P.Comercial!M52 -> 112.64444 | K12: =P.Comercial!N52 -> 203.91111 | L12: =P.Comercial!O52 -> 208.84444 | ... AN12: =P.Comercial!AQ52 -> 542.34313
A14: =Vaciado!C36 -> Servidor por cliente: | B14: =SUM(E14:P14) -> 32.5 | C14: =SUM(Q14:AB14) -> 64.375 | D14: =SUM(AC14:AN14) -> 101.75 | E14: =(E4+E5)*(Vaciado!$D$36/1000) -> 0.125 | F14: =(F4+F5)*(Vaciado!$D$36/1000) -> 0 | G14: =(G4+G5)*(Vaciado!$D$36/1000) -> 0.25 | H14: =(H4+H5)*(Vaciado!$D$36/1000) -> 0.875 | I14: =(I4+I5)*(Vaciado!$D$36/1000) -> 2.375 | J14: =(J4+J5)*(Vaciado!$D$36/1000) -> 2.375 | K14: =(K4+K5)*(Vaciado!$D$36/1000) -> 3.75 | L14: =(L4+L5)*(Vaciado!$D$36/1000) -> 4.25 | ... AN14: =(AN4+AN5)*(Vaciado!$D$36/1000) -> 12
A15: =Vaciado!C60 -> Soporte | B15: =SUM(E15:P15) -> 0 | C15: =SUM(Q15:AB15) -> 21 | D15: =SUM(AC15:AN15) -> 22.05 | E15: =(INT(E8/Vaciado!$I$60)+1)*(IF(Vaciado!$F$60>Flujos!E1,0,Vaciado!$E$60)) -> 0 | F15: =(INT(F8/Vaciado!$I$60)+1)*(IF(Vaciado!$F$60>Flujos!F1,0,Vaciado!$E$60)) -> 0 | G15: =(INT(G8/Vaciado!$I$60)+1)*(IF(Vaciado!$F$60>Flujos!G1,0,Vaciado!$E$60)) -> 0 | H15: =(INT(H8/Vaciado!$I$60)+1)*(IF(Vaciado!$F$60>Flujos!H1,0,Vaciado!$E$60)) -> 0 | I15: =(INT(I8/Vaciado!$I$60)+1)*(IF(Vaciado!$F$60>Flujos!I1,0,Vaciado!$E$60)) -> 0 | J15: =(INT(J8/Vaciado!$I$60)+1)*(IF(Vaciado!$F$60>Flujos!J1,0,Vaciado!$E$60)) -> 0 | K15: =(INT(K8/Vaciado!$I$60)+1)*(IF(Vaciado!$F$60>Flujos!K1,0,Vaciado!$E$60)) -> 0 | L15: =(INT(L8/Vaciado!$I$60)+1)*(IF(Vaciado!$F$60>Flujos!L1,0,Vaciado!$E$60)) -> 0 | ... P15: =(INT(P8/Vaciado!$I$60)+1)*(IF(Vaciado!$F$60>Flujos!P1,0,Vaciado!$E$60)) -> 0 | Q15: =(INT(Q8/Vaciado!$I$60)+1)*(IF(Vaciado!$F$60>Flujos!Q1,0,(Vaciado!$E$60*(1+Vaciado!$G$60)))) -> 1.75 | R15: =(INT(R8/Vaciado!$I$60)+1)*(IF(Vaciado!$F$60>Flujos!R1,0,(Vaciado!$E$60*(1+Vaciado!$G$60)))) -> 1.75 | S15: =(INT(S8/Vaciado!$I$60)+1)*(IF(Vaciado!$F$60>Flujos!S1,0,(Vaciado!$E$60*(1+Vaciado!$G$60)))) -> 1.75 | T15: =(INT(T8/Vaciado!$I$60)+1)*(IF(Vaciado!$F$60>Flujos!T1,0,(Vaciado!$E$60*(1+Vaciado!$G$60)))) -> 1.75 | U15: =(INT(U8/Vaciado!$I$60)+1)*(IF(Vaciado!$F$60>Flujos!U1,0,(Vaciado!$E$60*(1+Vaciado!$G$60)))) -> 1.75 | V15: =(INT(V8/Vaciado!$I$60)+1)*(IF(Vaciado!$F$60>Flujos!V1,0,(Vaciado!$E$60*(1+Vaciado!$G$60)))) -> 1.75 | W15: =(INT(W8/Vaciado!$I$60)+1)*(IF(Vaciado!$F$60>Flujos!W1,0,(Vaciado!$E$60*(1+Vaciado!$G$60)))) -> 1.75 | X15: =(INT(X8/Vaciado!$I$60)+1)*(IF(Vaciado!$F$60>Flujos!X1,0,(Vaciado!$E$60*(1+Vaciado!$G$60)))) -> 1.75 | ... AB15: =(INT(AB8/Vaciado!$I$60)+1)*(IF(Vaciado!$F$60>Flujos!AB1,0,(Vaciado!$E$60*(1+Vaciado!$G$60)))) -> 1.75 | AC15: =(INT(AC8/Vaciado!$I$60)+1)*(IF(Vaciado!$F$60>Flujos!AC1,0,(Vaciado!$E$60*((1+Vaciado!$G$60)^2)))) -> 1.8375 | AD15: =(INT(AD8/Vaciado!$I$60)+1)*(IF(Vaciado!$F$60>Flujos!AD1,0,(Vaciado!$E$60*((1+Vaciado!$G$60)^2)))) -> 1.8375 | AE15: =(INT(AE8/Vaciado!$I$60)+1)*(IF(Vaciado!$F$60>Flujos!AE1,0,(Vaciado!$E$60*((1+Vaciado!$G$60)^2)))) -> 1.8375 | AF15: =(INT(AF8/Vaciado!$I$60)+1)*(IF(Vaciado!$F$60>Flujos!AF1,0,(Vaciado!$E$60*((1+Vaciado!$G$60)^2)))) -> 1.8375 | AG15: =(INT(AG8/Vaciado!$I$60)+1)*(IF(Vaciado!$F$60>Flujos!AG1,0,(Vaciado!$E$60*((1+Vaciado!$G$60)^2)))) -> 1.8375 | AH15: =(INT(AH8/Vaciado!$I$60)+1)*(IF(Vaciado!$F$60>Flujos!AH1,0,(Vaciado!$E$60*((1+Vaciado!$G$60)^2)))) -> 1.8375 | AI15: =(INT(AI8/Vaciado!$I$60)+1)*(IF(Vaciado!$F$60>Flujos!AI1,0,(Vaciado!$E$60*((1+Vaciado!$G$60)^2)))) -> 1.8375 | AJ15: =(INT(AJ8/Vaciado!$I$60)+1)*(IF(Vaciado!$F$60>Flujos!AJ1,0,(Vaciado!$E$60*((1+Vaciado!$G$60)^2)))) -> 1.8375 | ... AN15: =(INT(AN8/Vaciado!$I$60)+1)*(IF(Vaciado!$F$60>Flujos!AN1,0,(Vaciado!$E$60*((1+Vaciado!$G$60)^2)))) -> 1.8375
A16: =Vaciado!C61 -> Operador | B16: =SUM(E16:P16) -> 13.333333 | C16: =SUM(Q16:AB16) -> 14 | D16: =SUM(AC16:AN16) -> 14.7 | E16: =(INT(E8/Vaciado!$I$61)+1)*(IF(Vaciado!$F$61>Flujos!E1,0,Vaciado!$E$61)) -> 1.1111111 | F16: =(INT(F8/Vaciado!$I$61)+1)*(IF(Vaciado!$F$61>Flujos!F1,0,Vaciado!$E$61)) -> 1.1111111 | G16: =(INT(G8/Vaciado!$I$61)+1)*(IF(Vaciado!$F$61>Flujos!G1,0,Vaciado!$E$61)) -> 1.1111111 | H16: =(INT(H8/Vaciado!$I$61)+1)*(IF(Vaciado!$F$61>Flujos!H1,0,Vaciado!$E$61)) -> 1.1111111 | I16: =(INT(I8/Vaciado!$I$61)+1)*(IF(Vaciado!$F$61>Flujos!I1,0,Vaciado!$E$61)) -> 1.1111111 | J16: =(INT(J8/Vaciado!$I$61)+1)*(IF(Vaciado!$F$61>Flujos!J1,0,Vaciado!$E$61)) -> 1.1111111 | K16: =(INT(K8/Vaciado!$I$61)+1)*(IF(Vaciado!$F$61>Flujos!K1,0,Vaciado!$E$61)) -> 1.1111111 | L16: =(INT(L8/Vaciado!$I$61)+1)*(IF(Vaciado!$F$61>Flujos!L1,0,Vaciado!$E$61)) -> 1.1111111 | ... P16: =(INT(P8/Vaciado!$I$61)+1)*(IF(Vaciado!$F$61>Flujos!P1,0,Vaciado!$E$61)) -> 1.1111111 | Q16: =(INT(Q8/Vaciado!$I$61)+1)*(IF(Vaciado!$F$61>Flujos!Q1,0,(Vaciado!$E$61*(1+Vaciado!$G$61)))) -> 1.1666667 | R16: =(INT(R8/Vaciado!$I$61)+1)*(IF(Vaciado!$F$61>Flujos!R1,0,(Vaciado!$E$61*(1+Vaciado!$G$61)))) -> 1.1666667 | S16: =(INT(S8/Vaciado!$I$61)+1)*(IF(Vaciado!$F$61>Flujos!S1,0,(Vaciado!$E$61*(1+Vaciado!$G$61)))) -> 1.1666667 | T16: =(INT(T8/Vaciado!$I$61)+1)*(IF(Vaciado!$F$61>Flujos!T1,0,(Vaciado!$E$61*(1+Vaciado!$G$61)))) -> 1.1666667 | U16: =(INT(U8/Vaciado!$I$61)+1)*(IF(Vaciado!$F$61>Flujos!U1,0,(Vaciado!$E$61*(1+Vaciado!$G$61)))) -> 1.1666667 | V16: =(INT(V8/Vaciado!$I$61)+1)*(IF(Vaciado!$F$61>Flujos!V1,0,(Vaciado!$E$61*(1+Vaciado!$G$61)))) -> 1.1666667 | W16: =(INT(W8/Vaciado!$I$61)+1)*(IF(Vaciado!$F$61>Flujos!W1,0,(Vaciado!$E$61*(1+Vaciado!$G$61)))) -> 1.1666667 | X16: =(INT(X8/Vaciado!$I$61)+1)*(IF(Vaciado!$F$61>Flujos!X1,0,(Vaciado!$E$61*(1+Vaciado!$G$61)))) -> 1.1666667 | ... AB16: =(INT(AB8/Vaciado!$I$61)+1)*(IF(Vaciado!$F$61>Flujos!AB1,0,(Vaciado!$E$61*(1+Vaciado!$G$61)))) -> 1.1666667 | AC16: =(INT(AC8/Vaciado!$I$61)+1)*(IF(Vaciado!$F$61>Flujos!AC1,0,(Vaciado!$E$61*((1+Vaciado!$G$61)^2)))) -> 1.225 | AD16: =(INT(AD8/Vaciado!$I$61)+1)*(IF(Vaciado!$F$61>Flujos!AD1,0,(Vaciado!$E$61*((1+Vaciado!$G$61)^2)))) -> 1.225 | AE16: =(INT(AE8/Vaciado!$I$61)+1)*(IF(Vaciado!$F$61>Flujos!AE1,0,(Vaciado!$E$61*((1+Vaciado!$G$61)^2)))) -> 1.225 | AF16: =(INT(AF8/Vaciado!$I$61)+1)*(IF(Vaciado!$F$61>Flujos!AF1,0,(Vaciado!$E$61*((1+Vaciado!$G$61)^2)))) -> 1.225 | AG16: =(INT(AG8/Vaciado!$I$61)+1)*(IF(Vaciado!$F$61>Flujos!AG1,0,(Vaciado!$E$61*((1+Vaciado!$G$61)^2)))) -> 1.225 | AH16: =(INT(AH8/Vaciado!$I$61)+1)*(IF(Vaciado!$F$61>Flujos!AH1,0,(Vaciado!$E$61*((1+Vaciado!$G$61)^2)))) -> 1.225 | AI16: =(INT(AI8/Vaciado!$I$61)+1)*(IF(Vaciado!$F$61>Flujos!AI1,0,(Vaciado!$E$61*((1+Vaciado!$G$61)^2)))) -> 1.225 | AJ16: =(INT(AJ8/Vaciado!$I$61)+1)*(IF(Vaciado!$F$61>Flujos!AJ1,0,(Vaciado!$E$61*((1+Vaciado!$G$61)^2)))) -> 1.225 | ... AN16: =(INT(AN8/Vaciado!$I$61)+1)*(IF(Vaciado!$F$61>Flujos!AN1,0,(Vaciado!$E$61*((1+Vaciado!$G$61)^2)))) -> 1.225
A17: =Vaciado!C62 -> Expertos Revisión | B17: =SUM(E17:P17) -> 5.5555556 | C17: =SUM(Q17:AB17) -> 17.5 | D17: =SUM(AC17:AN17) -> 18.375 | E17: =IF(Vaciado!$F$62>Flujos!E1,0,Vaciado!$E$62) -> 0 | F17: =IF(Vaciado!$F$62>Flujos!F1,0,Vaciado!$E$62) -> 0 | G17: =IF(Vaciado!$F$62>Flujos!G1,0,Vaciado!$E$62) -> 0 | H17: =IF(Vaciado!$F$62>Flujos!H1,0,Vaciado!$E$62) -> 0 | I17: =IF(Vaciado!$F$62>Flujos!I1,0,Vaciado!$E$62) -> 0 | J17: =IF(Vaciado!$F$62>Flujos!J1,0,Vaciado!$E$62) -> 0 | K17: =IF(Vaciado!$F$62>Flujos!K1,0,Vaciado!$E$62) -> 0 | L17: =IF(Vaciado!$F$62>Flujos!L1,0,Vaciado!$E$62) -> 0 | ... P17: =IF(Vaciado!$F$62>Flujos!P1,0,Vaciado!$E$62) -> 1.3888889 | Q17: =IF(Vaciado!$F$62>Flujos!Q1,0,(Vaciado!$E$62*(1+Vaciado!$G$62))) -> 1.4583333 | R17: =IF(Vaciado!$F$62>Flujos!R1,0,(Vaciado!$E$62*(1+Vaciado!$G$62))) -> 1.4583333 | S17: =IF(Vaciado!$F$62>Flujos!S1,0,(Vaciado!$E$62*(1+Vaciado!$G$62))) -> 1.4583333 | T17: =IF(Vaciado!$F$62>Flujos!T1,0,(Vaciado!$E$62*(1+Vaciado!$G$62))) -> 1.4583333 | U17: =IF(Vaciado!$F$62>Flujos!U1,0,(Vaciado!$E$62*(1+Vaciado!$G$62))) -> 1.4583333 | V17: =IF(Vaciado!$F$62>Flujos!V1,0,(Vaciado!$E$62*(1+Vaciado!$G$62))) -> 1.4583333 | W17: =IF(Vaciado!$F$62>Flujos!W1,0,(Vaciado!$E$62*(1+Vaciado!$G$62))) -> 1.4583333 | X17: =IF(Vaciado!$F$62>Flujos!X1,0,(Vaciado!$E$62*(1+Vaciado!$G$62))) -> 1.4583333 | ... AB17: =IF(Vaciado!$F$62>Flujos!AB1,0,(Vaciado!$E$62*(1+Vaciado!$G$62))) -> 1.4583333 | AC17: =IF(Vaciado!$F$62>Flujos!AC1,0,(Vaciado!$E$62*((1+Vaciado!$G$62)^2))) -> 1.53125 | AD17: =IF(Vaciado!$F$62>Flujos!AD1,0,(Vaciado!$E$62*((1+Vaciado!$G$62)^2))) -> 1.53125 | AE17: =IF(Vaciado!$F$62>Flujos!AE1,0,(Vaciado!$E$62*((1+Vaciado!$G$62)^2))) -> 1.53125 | AF17: =IF(Vaciado!$F$62>Flujos!AF1,0,(Vaciado!$E$62*((1+Vaciado!$G$62)^2))) -> 1.53125 | AG17: =IF(Vaciado!$F$62>Flujos!AG1,0,(Vaciado!$E$62*((1+Vaciado!$G$62)^2))) -> 1.53125 | AH17: =IF(Vaciado!$F$62>Flujos!AH1,0,(Vaciado!$E$62*((1+Vaciado!$G$62)^2))) -> 1.53125 | AI17: =IF(Vaciado!$F$62>Flujos!AI1,0,(Vaciado!$E$62*((1+Vaciado!$G$62)^2))) -> 1.53125 | AJ17: =IF(Vaciado!$F$62>Flujos!AJ1,0,(Vaciado!$E$62*((1+Vaciado!$G$62)^2))) -> 1.53125 | ... AN17: =IF(Vaciado!$F$62>Flujos!AN1,0,(Vaciado!$E$62*((1+Vaciado!$G$62)^2))) -> 1.53125
A18: =Vaciado!C69 -> Comisión Operador | B18: =SUM(E18:P18) -> 15.645643 | C18: =SUM(Q18:AB18) -> 33.64821 | D18: =SUM(AC18:AN18) -> 51.603447 | E18: =IF(Vaciado!$F$61>Flujos!E1,0,P.Comercial!H52*Vaciado!$D$69) -> 0.012333333 | F18: =IF(Vaciado!$F$61>Flujos!F1,0,P.Comercial!I52*Vaciado!$D$69) -> 0 | G18: =IF(Vaciado!$F$61>Flujos!G1,0,P.Comercial!J52*Vaciado!$D$69) -> 0.053444444 | H18: =IF(Vaciado!$F$61>Flujos!H1,0,P.Comercial!K52*Vaciado!$D$69) -> 0.67422222 | I18: =IF(Vaciado!$F$61>Flujos!I1,0,P.Comercial!L52*Vaciado!$D$69) -> 1.1264444 | J18: =IF(Vaciado!$F$61>Flujos!J1,0,P.Comercial!M52*Vaciado!$D$69) -> 1.1264444 | K18: =IF(Vaciado!$F$61>Flujos!K1,0,P.Comercial!N52*Vaciado!$D$69) -> 2.0391111 | L18: =IF(Vaciado!$F$61>Flujos!L1,0,P.Comercial!O52*Vaciado!$D$69) -> 2.0884444 | ... AN18: =IF(Vaciado!$F$61>Flujos!AN1,0,P.Comercial!AQ52*Vaciado!$D$69) -> 5.4234313
A19: =Vaciado!C70 -> Comisión CTO | B19: =SUM(E19:P19) -> 54.759751 | C19: =SUM(Q19:AB19) -> 117.76874 | D19: =SUM(AC19:AN19) -> 180.61206 | E19: =IF(Vaciado!$F$58>Flujos!E1,0,P.Comercial!H52*Vaciado!$D$70) -> 0.043166667 | F19: =IF(Vaciado!$F$58>Flujos!F1,0,P.Comercial!I52*Vaciado!$D$70) -> 0 | G19: =IF(Vaciado!$F$58>Flujos!G1,0,P.Comercial!J52*Vaciado!$D$70) -> 0.18705556 | H19: =IF(Vaciado!$F$58>Flujos!H1,0,P.Comercial!K52*Vaciado!$D$70) -> 2.3597778 | I19: =IF(Vaciado!$F$58>Flujos!I1,0,P.Comercial!L52*Vaciado!$D$70) -> 3.9425556 | J19: =IF(Vaciado!$F$58>Flujos!J1,0,P.Comercial!M52*Vaciado!$D$70) -> 3.9425556 | K19: =IF(Vaciado!$F$58>Flujos!K1,0,P.Comercial!N52*Vaciado!$D$70) -> 7.1368889 | L19: =IF(Vaciado!$F$58>Flujos!L1,0,P.Comercial!O52*Vaciado!$D$70) -> 7.3095556 | ... AN19: =IF(Vaciado!$F$58>Flujos!AN1,0,P.Comercial!AQ52*Vaciado!$D$70) -> 18.98201
A20: Total Costos Operacionales | B20: =SUM(B14:B19) -> 121.79428 | C20: =SUM(C14:C19) -> 268.29195 | D20: =SUM(D14:D19) -> 389.09051 | E20: =SUM(E14:E19) -> 1.2916111 | F20: =SUM(F14:F19) -> 1.1111111 | G20: =SUM(G14:G19) -> 1.6016111 | H20: =SUM(H14:H19) -> 5.0201111 | I20: =SUM(I14:I19) -> 8.5551111 | ... AN20: =SUM(AN14:AN19) -> 40.999191
A22: =Vaciado!C50 -> Viaticos y viajes: | B22: =SUM(E22:P22) -> 6.6666667 | C22: =SUM(Q22:AB22) -> 6.6666667 | D22: =SUM(AC22:AN22) -> 6.6666667 | E22: =Vaciado!$E$50 -> 0.55555556 | F22: =Vaciado!$E$50 -> 0.55555556 | G22: =Vaciado!$E$50 -> 0.55555556 | H22: =Vaciado!$E$50 -> 0.55555556 | I22: =Vaciado!$E$50 -> 0.55555556 | J22: =Vaciado!$E$50 -> 0.55555556 | K22: =Vaciado!$E$50 -> 0.55555556 | L22: =Vaciado!$E$50 -> 0.55555556 | ... AN22: =Vaciado!$E$50 -> 0.55555556
A23: =Vaciado!C56 -> CCO | B23: =SUM(E23:P23) -> 18.666667 | C23: =SUM(Q23:AB23) -> 19.6 | D23: =SUM(AC23:AN23) -> 20.58 | E23: =IF(Vaciado!$F$56>Flujos!E1,0,Vaciado!$E$56) -> 1.5555556 | F23: =IF(Vaciado!$F$56>Flujos!F1,0,Vaciado!$E$56) -> 1.5555556 | G23: =IF(Vaciado!$F$56>Flujos!G1,0,Vaciado!$E$56) -> 1.5555556 | H23: =IF(Vaciado!$F$56>Flujos!H1,0,Vaciado!$E$56) -> 1.5555556 | I23: =IF(Vaciado!$F$56>Flujos!I1,0,Vaciado!$E$56) -> 1.5555556 | J23: =IF(Vaciado!$F$56>Flujos!J1,0,Vaciado!$E$56) -> 1.5555556 | K23: =IF(Vaciado!$F$56>Flujos!K1,0,Vaciado!$E$56) -> 1.5555556 | L23: =IF(Vaciado!$F$56>Flujos!L1,0,Vaciado!$E$56) -> 1.5555556 | ... P23: =IF(Vaciado!$F$56>Flujos!P1,0,Vaciado!$E$56) -> 1.5555556 | Q23: =IF(Vaciado!$F$56>Flujos!Q1,0,(Vaciado!$E$56*(1+Vaciado!$G$56))) -> 1.6333333 | R23: =IF(Vaciado!$F$56>Flujos!R1,0,(Vaciado!$E$56*(1+Vaciado!$G$56))) -> 1.6333333 | S23: =IF(Vaciado!$F$56>Flujos!S1,0,(Vaciado!$E$56*(1+Vaciado!$G$56))) -> 1.6333333 | T23: =IF(Vaciado!$F$56>Flujos!T1,0,(Vaciado!$E$56*(1+Vaciado!$G$56))) -> 1.6333333 | U23: =IF(Vaciado!$F$56>Flujos!U1,0,(Vaciado!$E$56*(1+Vaciado!$G$56))) -> 1.6333333 | V23: =IF(Vaciado!$F$56>Flujos!V1,0,(Vaciado!$E$56*(1+Vaciado!$G$56))) -> 1.6333333 | W23: =IF(Vaciado!$F$56>Flujos!W1,0,(Vaciado!$E$56*(1+Vaciado!$G$56))) -> 1.6333333 | X23: =IF(Vaciado!$F$56>Flujos!X1,0,(Vaciado!$E$56*(1+Vaciado!$G$56))) -> 1.6333333 | ... AB23: =IF(Vaciado!$F$56>Flujos!AB1,0,(Vaciado!$E$56*(1+Vaciado!$G$56))) -> 1.6333333 | AC23: =IF(Vaciado!$F$56>Flujos!AC1,0,(Vaciado!$E$56*((1+Vaciado!$G$56)^2))) -> 1.715 | AD23: =IF(Vaciado!$F$56>Flujos!AD1,0,(Vaciado!$E$56*((1+Vaciado!$G$56)^2))) -> 1.715 | AE23: =IF(Vaciado!$F$56>Flujos!AE1,0,(Vaciado!$E$56*((1+Vaciado!$G$56)^2))) -> 1.715 | AF23: =IF(Vaciado!$F$56>Flujos!AF1,0,(Vaciado!$E$56*((1+Vaciado!$G$56)^2))) -> 1.715 | AG23: =IF(Vaciado!$F$56>Flujos!AG1,0,(Vaciado!$E$56*((1+Vaciado!$G$56)^2))) -> 1.715 | AH23: =IF(Vaciado!$F$56>Flujos!AH1,0,(Vaciado!$E$56*((1+Vaciado!$G$56)^2))) -> 1.715 | AI23: =IF(Vaciado!$F$56>Flujos!AI1,0,(Vaciado!$E$56*((1+Vaciado!$G$56)^2))) -> 1.715 | AJ23: =IF(Vaciado!$F$56>Flujos!AJ1,0,(Vaciado!$E$56*((1+Vaciado!$G$56)^2))) -> 1.715 | ... AN23: =IF(Vaciado!$F$56>Flujos!AN1,0,(Vaciado!$E$56*((1+Vaciado!$G$56)^2))) -> 1.715
A24: =Vaciado!C57 -> KAM | B24: =SUM(E24:P24) -> 16 | C24: =SUM(Q24:AB24) -> 16.8 | D24: =SUM(AC24:AN24) -> 17.64 | E24: =(INT(E8/Vaciado!$I$57)+1)*(IF(Vaciado!$F$57>Flujos!E1,0,Vaciado!$E$57)) -> 1.3333333 | F24: =(INT(F8/Vaciado!$I$57)+1)*(IF(Vaciado!$F$57>Flujos!F1,0,Vaciado!$E$57)) -> 1.3333333 | G24: =(INT(G8/Vaciado!$I$57)+1)*(IF(Vaciado!$F$57>Flujos!G1,0,Vaciado!$E$57)) -> 1.3333333 | H24: =(INT(H8/Vaciado!$I$57)+1)*(IF(Vaciado!$F$57>Flujos!H1,0,Vaciado!$E$57)) -> 1.3333333 | I24: =(INT(I8/Vaciado!$I$57)+1)*(IF(Vaciado!$F$57>Flujos!I1,0,Vaciado!$E$57)) -> 1.3333333 | J24: =(INT(J8/Vaciado!$I$57)+1)*(IF(Vaciado!$F$57>Flujos!J1,0,Vaciado!$E$57)) -> 1.3333333 | K24: =(INT(K8/Vaciado!$I$57)+1)*(IF(Vaciado!$F$57>Flujos!K1,0,Vaciado!$E$57)) -> 1.3333333 | L24: =(INT(L8/Vaciado!$I$57)+1)*(IF(Vaciado!$F$57>Flujos!L1,0,Vaciado!$E$57)) -> 1.3333333 | ... P24: =(INT(P8/Vaciado!$I$57)+1)*(IF(Vaciado!$F$57>Flujos!P1,0,Vaciado!$E$57)) -> 1.3333333 | Q24: =(INT(Q8/Vaciado!$I$57)+1)*(IF(Vaciado!$F$57>Flujos!Q1,0,(Vaciado!$E$57*(1+Vaciado!$G$57)))) -> 1.4 | R24: =(INT(R8/Vaciado!$I$57)+1)*(IF(Vaciado!$F$57>Flujos!R1,0,(Vaciado!$E$57*(1+Vaciado!$G$57)))) -> 1.4 | S24: =(INT(S8/Vaciado!$I$57)+1)*(IF(Vaciado!$F$57>Flujos!S1,0,(Vaciado!$E$57*(1+Vaciado!$G$57)))) -> 1.4 | T24: =(INT(T8/Vaciado!$I$57)+1)*(IF(Vaciado!$F$57>Flujos!T1,0,(Vaciado!$E$57*(1+Vaciado!$G$57)))) -> 1.4 | U24: =(INT(U8/Vaciado!$I$57)+1)*(IF(Vaciado!$F$57>Flujos!U1,0,(Vaciado!$E$57*(1+Vaciado!$G$57)))) -> 1.4 | V24: =(INT(V8/Vaciado!$I$57)+1)*(IF(Vaciado!$F$57>Flujos!V1,0,(Vaciado!$E$57*(1+Vaciado!$G$57)))) -> 1.4 | W24: =(INT(W8/Vaciado!$I$57)+1)*(IF(Vaciado!$F$57>Flujos!W1,0,(Vaciado!$E$57*(1+Vaciado!$G$57)))) -> 1.4 | X24: =(INT(X8/Vaciado!$I$57)+1)*(IF(Vaciado!$F$57>Flujos!X1,0,(Vaciado!$E$57*(1+Vaciado!$G$57)))) -> 1.4 | ... AB24: =(INT(AB8/Vaciado!$I$57)+1)*(IF(Vaciado!$F$57>Flujos!AB1,0,(Vaciado!$E$57*(1+Vaciado!$G$57)))) -> 1.4 | AC24: =(INT(AC8/Vaciado!$I$57)+1)*(IF(Vaciado!$F$57>Flujos!AC1,0,(Vaciado!$E$57*((1+Vaciado!$G$57)^2)))) -> 1.47 | AD24: =(INT(AD8/Vaciado!$I$57)+1)*(IF(Vaciado!$F$57>Flujos!AD1,0,(Vaciado!$E$57*((1+Vaciado!$G$57)^2)))) -> 1.47 | AE24: =(INT(AE8/Vaciado!$I$57)+1)*(IF(Vaciado!$F$57>Flujos!AE1,0,(Vaciado!$E$57*((1+Vaciado!$G$57)^2)))) -> 1.47 | AF24: =(INT(AF8/Vaciado!$I$57)+1)*(IF(Vaciado!$F$57>Flujos!AF1,0,(Vaciado!$E$57*((1+Vaciado!$G$57)^2)))) -> 1.47 | AG24: =(INT(AG8/Vaciado!$I$57)+1)*(IF(Vaciado!$F$57>Flujos!AG1,0,(Vaciado!$E$57*((1+Vaciado!$G$57)^2)))) -> 1.47 | AH24: =(INT(AH8/Vaciado!$I$57)+1)*(IF(Vaciado!$F$57>Flujos!AH1,0,(Vaciado!$E$57*((1+Vaciado!$G$57)^2)))) -> 1.47 | AI24: =(INT(AI8/Vaciado!$I$57)+1)*(IF(Vaciado!$F$57>Flujos!AI1,0,(Vaciado!$E$57*((1+Vaciado!$G$57)^2)))) -> 1.47 | AJ24: =(INT(AJ8/Vaciado!$I$57)+1)*(IF(Vaciado!$F$57>Flujos!AJ1,0,(Vaciado!$E$57*((1+Vaciado!$G$57)^2)))) -> 1.47 | ... AN24: =(INT(AN8/Vaciado!$I$57)+1)*(IF(Vaciado!$F$57>Flujos!AN1,0,(Vaciado!$E$57*((1+Vaciado!$G$57)^2)))) -> 1.47
A25: =Vaciado!C72 -> Comisión CCO | B25: =SUM(E25:P25) -> 54.529529 | C25: =SUM(Q25:AB25) -> 117.76874 | D25: =SUM(AC25:AN25) -> 180.61206 | E25: =IF(E26=0,IF(IF(Vaciado!$F$57>Flujos!E1,0,(IF(Flujos!E12<Vaciado!$H$68,0,P.Comercial!H52*Vaciado!$F$72)))>E12*Vaciado!$G$69,Flujos!E12*Vaciado!$G$69,IF(Vaciado!$F$57>Flujos!E1,0,(IF(Flujos!E12<Vaciado!$H$68,0,P.Comercial!H52*Vaciado!$F$72)))),IF(IF(Vaciado!$F$57>Flujos!E1,0,(IF(Flujos!E12<Vaciado!$H$68,0,P.Comercial!H52*Vaciado!$D$72)))>E12*Vaciado!$G$69,Flujos!E12*Vaciado!$G$69,IF(Vaciado!$F$57>Flujos!E1,0,(IF(Flujos!E12<Vaciado!$H$68,0,P.Comercial!H52*Vaciado!$D$72))))) -> 0 | F25: =IF(F26=0,IF(IF(Vaciado!$F$57>Flujos!F1,0,(IF(Flujos!F12<Vaciado!$H$68,0,P.Comercial!I52*Vaciado!$F$72)))>F12*Vaciado!$G$69,Flujos!F12*Vaciado!$G$69,IF(Vaciado!$F$57>Flujos!F1,0,(IF(Flujos!F12<Vaciado!$H$68,0,P.Comercial!I52*Vaciado!$F$72)))),IF(IF(Vaciado!$F$57>Flujos!F1,0,(IF(Flujos!F12<Vaciado!$H$68,0,P.Comercial!I52*Vaciado!$D$72)))>F12*Vaciado!$G$69,Flujos!F12*Vaciado!$G$69,IF(Vaciado!$F$57>Flujos!F1,0,(IF(Flujos!F12<Vaciado!$H$68,0,P.Comercial!I52*Vaciado!$D$72))))) -> 0 | G25: =IF(G26=0,IF(IF(Vaciado!$F$57>Flujos!G1,0,(IF(Flujos!G12<Vaciado!$H$68,0,P.Comercial!J52*Vaciado!$F$72)))>G12*Vaciado!$G$69,Flujos!G12*Vaciado!$G$69,IF(Vaciado!$F$57>Flujos!G1,0,(IF(Flujos!G12<Vaciado!$H$68,0,P.Comercial!J52*Vaciado!$F$72)))),IF(IF(Vaciado!$F$57>Flujos!G1,0,(IF(Flujos!G12<Vaciado!$H$68,0,P.Comercial!J52*Vaciado!$D$72)))>G12*Vaciado!$G$69,Flujos!G12*Vaciado!$G$69,IF(Vaciado!$F$57>Flujos!G1,0,(IF(Flujos!G12<Vaciado!$H$68,0,P.Comercial!J52*Vaciado!$D$72))))) -> 0 | H25: =IF(H26=0,IF(IF(Vaciado!$F$57>Flujos!H1,0,(IF(Flujos!H12<Vaciado!$H$68,0,P.Comercial!K52*Vaciado!$F$72)))>H12*Vaciado!$G$69,Flujos!H12*Vaciado!$G$69,IF(Vaciado!$F$57>Flujos!H1,0,(IF(Flujos!H12<Vaciado!$H$68,0,P.Comercial!K52*Vaciado!$F$72)))),IF(IF(Vaciado!$F$57>Flujos!H1,0,(IF(Flujos!H12<Vaciado!$H$68,0,P.Comercial!K52*Vaciado!$D$72)))>H12*Vaciado!$G$69,Flujos!H12*Vaciado!$G$69,IF(Vaciado!$F$57>Flujos!H1,0,(IF(Flujos!H12<Vaciado!$H$68,0,P.Comercial!K52*Vaciado!$D$72))))) -> 2.3597778 | I25: =IF(I26=0,IF(IF(Vaciado!$F$57>Flujos!I1,0,(IF(Flujos!I12<Vaciado!$H$68,0,P.Comercial!L52*Vaciado!$F$72)))>I12*Vaciado!$G$69,Flujos!I12*Vaciado!$G$69,IF(Vaciado!$F$57>Flujos!I1,0,(IF(Flujos!I12<Vaciado!$H$68,0,P.Comercial!L52*Vaciado!$F$72)))),IF(IF(Vaciado!$F$57>Flujos!I1,0,(IF(Flujos!I12<Vaciado!$H$68,0,P.Comercial!L52*Vaciado!$D$72)))>I12*Vaciado!$G$69,Flujos!I12*Vaciado!$G$69,IF(Vaciado!$F$57>Flujos!I1,0,(IF(Flujos!I12<Vaciado!$H$68,0,P.Comercial!L52*Vaciado!$D$72))))) -> 3.9425556 | J25: =IF(J26=0,IF(IF(Vaciado!$F$57>Flujos!J1,0,(IF(Flujos!J12<Vaciado!$H$68,0,P.Comercial!M52*Vaciado!$F$72)))>J12*Vaciado!$G$69,Flujos!J12*Vaciado!$G$69,IF(Vaciado!$F$57>Flujos!J1,0,(IF(Flujos!J12<Vaciado!$H$68,0,P.Comercial!M52*Vaciado!$F$72)))),IF(IF(Vaciado!$F$57>Flujos!J1,0,(IF(Flujos!J12<Vaciado!$H$68,0,P.Comercial!M52*Vaciado!$D$72)))>J12*Vaciado!$G$69,Flujos!J12*Vaciado!$G$69,IF(Vaciado!$F$57>Flujos!J1,0,(IF(Flujos!J12<Vaciado!$H$68,0,P.Comercial!M52*Vaciado!$D$72))))) -> 3.9425556 | K25: =IF(K26=0,IF(IF(Vaciado!$F$57>Flujos!K1,0,(IF(Flujos!K12<Vaciado!$H$68,0,P.Comercial!N52*Vaciado!$F$72)))>K12*Vaciado!$G$69,Flujos!K12*Vaciado!$G$69,IF(Vaciado!$F$57>Flujos!K1,0,(IF(Flujos!K12<Vaciado!$H$68,0,P.Comercial!N52*Vaciado!$F$72)))),IF(IF(Vaciado!$F$57>Flujos!K1,0,(IF(Flujos!K12<Vaciado!$H$68,0,P.Comercial!N52*Vaciado!$D$72)))>K12*Vaciado!$G$69,Flujos!K12*Vaciado!$G$69,IF(Vaciado!$F$57>Flujos!K1,0,(IF(Flujos!K12<Vaciado!$H$68,0,P.Comercial!N52*Vaciado!$D$72))))) -> 7.1368889 | L25: =IF(L26=0,IF(IF(Vaciado!$F$57>Flujos!L1,0,(IF(Flujos!L12<Vaciado!$H$68,0,P.Comercial!O52*Vaciado!$F$72)))>L12*Vaciado!$G$69,Flujos!L12*Vaciado!$G$69,IF(Vaciado!$F$57>Flujos!L1,0,(IF(Flujos!L12<Vaciado!$H$68,0,P.Comercial!O52*Vaciado!$F$72)))),IF(IF(Vaciado!$F$57>Flujos!L1,0,(IF(Flujos!L12<Vaciado!$H$68,0,P.Comercial!O52*Vaciado!$D$72)))>L12*Vaciado!$G$69,Flujos!L12*Vaciado!$G$69,IF(Vaciado!$F$57>Flujos!L1,0,(IF(Flujos!L12<Vaciado!$H$68,0,P.Comercial!O52*Vaciado!$D$72))))) -> 7.3095556 | ... AN25: =IF(AN26=0,IF(IF(Vaciado!$F$57>Flujos!AN1,0,(IF(Flujos!AN12<Vaciado!$H$68,0,P.Comercial!AQ52*Vaciado!$F$72)))>AN12*Vaciado!$G$69,Flujos!AN12*Vaciado!$G$69,IF(Vaciado!$F$57>Flujos!AN1,0,(IF(Flujos!AN12<Vaciado!$H$68,0,P.Comercial!AQ52*Vaciado!$F$72)))),IF(IF(Vaciado!$F$57>Flujos!AN1,0,(IF(Flujos!AN12<Vaciado!$H$68,0,P.Comercial!AQ52*Vaciado!$D$72)))>AN12*Vaciado!$G$69,Flujos!AN12*Vaciado!$G$69,IF(Vaciado!$F$57>Flujos!AN1,0,(IF(Flujos!AN12<Vaciado!$H$68,0,P.Comercial!AQ52*Vaciado!$D$72))))) -> 18.98201
A26: =Vaciado!C71 -> Comisión KAM | B26: =SUM(E26:P26) -> 54.529529 | C26: =SUM(Q26:AB26) -> 117.76874 | D26: =SUM(AC26:AN26) -> 180.61206 | E26: =IF(IF(Vaciado!$F$57>Flujos!E1,0,(IF(Flujos!E12<Vaciado!$H$68,0,P.Comercial!H52*Vaciado!$D$71)))>E12*Vaciado!$G$69,Flujos!E12*Vaciado!$G$69,IF(Vaciado!$F$57>Flujos!E1,0,(IF(Flujos!E12<Vaciado!$H$68,0,P.Comercial!H52*Vaciado!$D$71)))) -> 0 | F26: =IF(IF(Vaciado!$F$57>Flujos!F1,0,(IF(Flujos!F12<Vaciado!$H$68,0,P.Comercial!I52*Vaciado!$D$71)))>F12*Vaciado!$G$69,Flujos!F12*Vaciado!$G$69,IF(Vaciado!$F$57>Flujos!F1,0,(IF(Flujos!F12<Vaciado!$H$68,0,P.Comercial!I52*Vaciado!$D$71)))) -> 0 | G26: =IF(IF(Vaciado!$F$57>Flujos!G1,0,(IF(Flujos!G12<Vaciado!$H$68,0,P.Comercial!J52*Vaciado!$D$71)))>G12*Vaciado!$G$69,Flujos!G12*Vaciado!$G$69,IF(Vaciado!$F$57>Flujos!G1,0,(IF(Flujos!G12<Vaciado!$H$68,0,P.Comercial!J52*Vaciado!$D$71)))) -> 0 | H26: =IF(IF(Vaciado!$F$57>Flujos!H1,0,(IF(Flujos!H12<Vaciado!$H$68,0,P.Comercial!K52*Vaciado!$D$71)))>H12*Vaciado!$G$69,Flujos!H12*Vaciado!$G$69,IF(Vaciado!$F$57>Flujos!H1,0,(IF(Flujos!H12<Vaciado!$H$68,0,P.Comercial!K52*Vaciado!$D$71)))) -> 2.3597778 | I26: =IF(IF(Vaciado!$F$57>Flujos!I1,0,(IF(Flujos!I12<Vaciado!$H$68,0,P.Comercial!L52*Vaciado!$D$71)))>I12*Vaciado!$G$69,Flujos!I12*Vaciado!$G$69,IF(Vaciado!$F$57>Flujos!I1,0,(IF(Flujos!I12<Vaciado!$H$68,0,P.Comercial!L52*Vaciado!$D$71)))) -> 3.9425556 | J26: =IF(IF(Vaciado!$F$57>Flujos!J1,0,(IF(Flujos!J12<Vaciado!$H$68,0,P.Comercial!M52*Vaciado!$D$71)))>J12*Vaciado!$G$69,Flujos!J12*Vaciado!$G$69,IF(Vaciado!$F$57>Flujos!J1,0,(IF(Flujos!J12<Vaciado!$H$68,0,P.Comercial!M52*Vaciado!$D$71)))) -> 3.9425556 | K26: =IF(IF(Vaciado!$F$57>Flujos!K1,0,(IF(Flujos!K12<Vaciado!$H$68,0,P.Comercial!N52*Vaciado!$D$71)))>K12*Vaciado!$G$69,Flujos!K12*Vaciado!$G$69,IF(Vaciado!$F$57>Flujos!K1,0,(IF(Flujos!K12<Vaciado!$H$68,0,P.Comercial!N52*Vaciado!$D$71)))) -> 7.1368889 | L26: =IF(IF(Vaciado!$F$57>Flujos!L1,0,(IF(Flujos!L12<Vaciado!$H$68,0,P.Comercial!O52*Vaciado!$D$71)))>L12*Vaciado!$G$69,Flujos!L12*Vaciado!$G$69,IF(Vaciado!$F$57>Flujos!L1,0,(IF(Flujos!L12<Vaciado!$H$68,0,P.Comercial!O52*Vaciado!$D$71)))) -> 7.3095556 | ... AN26: =IF(IF(Vaciado!$F$57>Flujos!AN1,0,(IF(Flujos!AN12<Vaciado!$H$68,0,P.Comercial!AQ52*Vaciado!$D$71)))>AN12*Vaciado!$G$69,Flujos!AN12*Vaciado!$G$69,IF(Vaciado!$F$57>Flujos!AN1,0,(IF(Flujos!AN12<Vaciado!$H$68,0,P.Comercial!AQ52*Vaciado!$D$71)))) -> 18.98201
A27: =Vaciado!C51 -> Comisión Partner: | B27: =SUM(E27:P27) -> 234.68465 | C27: =SUM(Q27:AB27) -> 504.72316 | D27: =SUM(AC27:AN27) -> 774.0517 | E27: =E12*Vaciado!$D$51 -> 0.185 | F27: =F12*Vaciado!$D$51 -> 0 | G27: =G12*Vaciado!$D$51 -> 0.80166667 | H27: =H12*Vaciado!$D$51 -> 10.113333 | I27: =I12*Vaciado!$D$51 -> 16.896667 | J27: =J12*Vaciado!$D$51 -> 16.896667 | K27: =K12*Vaciado!$D$51 -> 30.586667 | L27: =L12*Vaciado!$D$51 -> 31.326667 | ... AN27: =AN12*Vaciado!$D$51 -> 81.35147
A28: Total gastos del CAC | B28: =SUM(B22:B27) -> 385.07704 | C28: =SUM(C22:C27) -> 783.32729 | D28: =SUM(D22:D27) -> 1180.1625 | E28: =SUM(E22:E27) -> 3.6294444 | F28: =SUM(F22:F27) -> 3.4444444 | G28: =SUM(G22:G27) -> 4.2461111 | H28: =SUM(H22:H27) -> 18.277333 | I28: =SUM(I22:I27) -> 28.226222 | ... AN28: =SUM(AN22:AN27) -> 123.05604
A30: =Vaciado!C39 -> Costos de Cloud mensual: | B30: =SUM(E30:P30) -> 1.5 | C30: =SUM(Q30:AB30) -> 1.5 | D30: =SUM(AC30:AN30) -> 1.5 | E30: =Vaciado!$D$39/1000 -> 0.125 | F30: =Vaciado!$D$39/1000 -> 0.125 | G30: =Vaciado!$D$39/1000 -> 0.125 | H30: =Vaciado!$D$39/1000 -> 0.125 | I30: =Vaciado!$D$39/1000 -> 0.125 | J30: =Vaciado!$D$39/1000 -> 0.125 | K30: =Vaciado!$D$39/1000 -> 0.125 | L30: =Vaciado!$D$39/1000 -> 0.125 | ... AN30: =Vaciado!$D$39/1000 -> 0.125
